2023-06-01 03:01:29,913 INFO    StreamThr :1304 [internal.py:wandb_internal():86] W&B internal server running at pid: 1304, started at: 2023-06-01 03:01:29.912778
2023-06-01 03:01:29,913 DEBUG   HandlerThread:1304 [handler.py:handle_request():144] handle_request: status
2023-06-01 03:01:29,918 INFO    WriterThread:1304 [datastore.py:open_for_write():85] open: /embodied/wandb/run-20230601_030129-axet6lqw/run-axet6lqw.wandb
2023-06-01 03:01:29,918 DEBUG   SenderThread:1304 [sender.py:send():375] send: header
2023-06-01 03:01:29,935 DEBUG   SenderThread:1304 [sender.py:send():375] send: run
2023-06-01 03:01:30,476 ERROR   SenderThread:1304 [internal_api.py:execute():288] 404 response executing GraphQL.
2023-06-01 03:01:30,477 ERROR   SenderThread:1304 [internal_api.py:execute():289] {"errors":[{"message":"project not found","path":["upsertBucket"]}],"data":{"upsertBucket":null}}
2023-06-01 03:01:30,477 ERROR   SenderThread:1304 [sender.py:send_run():979] It appears that you do not have permission to access the requested resource. Please reach out to the project owner to grant you access. If you have the correct permissions, verify that there are no issues with your networking setup.(Error 404: Not Found)
Traceback (most recent call last):
  File "/usr/local/lib/python3.8/dist-packages/wandb/sdk/lib/retry.py", line 131, in __call__
    result = self._call_fn(*args, **kwargs)
  File "/usr/local/lib/python3.8/dist-packages/wandb/sdk/internal/internal_api.py", line 285, in execute
    return self.client.execute(*args, **kwargs)  # type: ignore
  File "/usr/local/lib/python3.8/dist-packages/wandb/vendor/gql-0.2.0/wandb_gql/client.py", line 52, in execute
    result = self._get_result(document, *args, **kwargs)
  File "/usr/local/lib/python3.8/dist-packages/wandb/vendor/gql-0.2.0/wandb_gql/client.py", line 60, in _get_result
    return self.transport.execute(document, *args, **kwargs)
  File "/usr/local/lib/python3.8/dist-packages/wandb/sdk/lib/gql_request.py", line 56, in execute
    request.raise_for_status()
  File "/usr/lib/python3/dist-packages/requests/models.py", line 940, in raise_for_status
    raise HTTPError(http_error_msg, response=self)
requests.exceptions.HTTPError: 404 Client Error: Not Found for url: https://api.wandb.ai/graphql

During handling of the above exception, another exception occurred:

Traceback (most recent call last):
  File "/usr/local/lib/python3.8/dist-packages/wandb/sdk/internal/sender.py", line 977, in send_run
    self._init_run(run, config_value_dict)
  File "/usr/local/lib/python3.8/dist-packages/wandb/sdk/internal/sender.py", line 1015, in _init_run
    server_run, inserted, server_messages = self._api.upsert_run(
  File "/usr/local/lib/python3.8/dist-packages/wandb/apis/normalize.py", line 73, in wrapper
    raise err
  File "/usr/local/lib/python3.8/dist-packages/wandb/apis/normalize.py", line 41, in wrapper
    return func(*args, **kwargs)
  File "/usr/local/lib/python3.8/dist-packages/wandb/sdk/internal/internal_api.py", line 1690, in upsert_run
    response = self.gql(
  File "/usr/local/lib/python3.8/dist-packages/wandb/sdk/internal/internal_api.py", line 257, in gql
    ret = self._retry_gql(
  File "/usr/local/lib/python3.8/dist-packages/wandb/sdk/lib/retry.py", line 147, in __call__
    retry_timedelta_triggered = check_retry_fn(e)
  File "/usr/local/lib/python3.8/dist-packages/wandb/util.py", line 907, in check_retry_fn
    return fallback_retry_fn(e)
  File "/usr/local/lib/python3.8/dist-packages/wandb/util.py", line 849, in no_retry_auth
    raise CommError(
wandb.errors.CommError: It appears that you do not have permission to access the requested resource. Please reach out to the project owner to grant you access. If you have the correct permissions, verify that there are no issues with your networking setup.(Error 404: Not Found)
2023-06-01 03:01:30,837 DEBUG   HandlerThread:1304 [handler.py:handle_request():144] handle_request: shutdown
2023-06-01 03:01:30,838 INFO    HandlerThread:1304 [handler.py:finish():842] shutting down handler
2023-06-01 03:01:30,936 INFO    WriterThread:1304 [datastore.py:close():298] close: /embodied/wandb/run-20230601_030129-axet6lqw/run-axet6lqw.wandb
2023-06-01 03:01:31,480 INFO    SenderThread:1304 [sender.py:finish():1550] shutting down sender
